Workbook

Sheet ①サマリ
A1: サマリ
A2: スタートアップ定義(収載基準)+③④の自動集計
A4: A. スタートアップ定義(収載6基準)
A5: # | B5: 基準 | C5: 内容
A6: 1 | B6: 未上場 | C6: 上場企業・連結子会社・買収済みは除外(カーブアウトは可)
A7: 2 | B7: 設立年数 | C7: 10年以内(ディープテックは15年以内まで許容)
A8: 3 | B8: 外部資金調達 | C8: エクイティ調達実績あり(国内は必須。助成金・融資のみは△)
A9: 4 | B9: 成長志向 | C9: スケール可能な製品・サービス(受託専業は除外)
A10: 5 | B10: 規模 | C10: 従業員おおむね500名未満(目安)
A11: 6 | B11: 独立性 | C11: 大企業グループ中核子会社・JVは原則除外
A13: B. スタートアップDB集計(業界分類×国内外)
A14: 業界分類 | B14: 国内 | C14: 海外 | D14: 合計
A15: AI・データ基盤 | B15: =COUNTIFS('③スタートアップDB'!C5:C5,A15,'③スタートアップDB'!G5:G5,"日本") | C15: =COUNTIFS('③スタートアップDB'!C5:C5,A15)-B15 | D15: =B15+C15
A16: エンタープライズSaaS・業務DX | B16: =COUNTIFS('③スタートアップDB'!C5:C5,A16,'③スタートアップDB'!G5:G5,"日本") | C16: =COUNTIFS('③スタートアップDB'!C5:C5,A16)-B16 | D16: =B16+C16
A17: フィンテック・保険 | B17: =COUNTIFS('③スタートアップDB'!C5:C5,A17,'③スタートアップDB'!G5:G5,"日本") | C17: =COUNTIFS('③スタートアップDB'!C5:C5,A17)-B17 | D17: =B17+C17
A18: ヘルスケア・医療機器 | B18: =COUNTIFS('③スタートアップDB'!C5:C5,A18,'③スタートアップDB'!G5:G5,"日本") | C18: =COUNTIFS('③スタートアップDB'!C5:C5,A18)-B18 | D18: =B18+C18
A19: バイオ・創薬 | B19: =COUNTIFS('③スタートアップDB'!C5:C5,A19,'③スタートアップDB'!G5:G5,"日本") | C19: =COUNTIFS('③スタートアップDB'!C5:C5,A19)-B19 | D19: =B19+C19
A20: モビリティ・自動車 | B20: =COUNTIFS('③スタートアップDB'!C5:C5,A20,'③スタートアップDB'!G5:G5,"日本") | C20: =COUNTIFS('③スタートアップDB'!C5:C5,A20)-B20 | D20: =B20+C20
A21: 宇宙・航空・防衛 | B21: =COUNTIFS('③スタートアップDB'!C5:C5,A21,'③スタートアップDB'!G5:G5,"日本") | C21: =COUNTIFS('③スタートアップDB'!C5:C5,A21)-B21 | D21: =B21+C21
A22: エネルギー・クリーンテック | B22: =COUNTIFS('③スタートアップDB'!C5:C5,A22,'③スタートアップDB'!G5:G5,"日本") | C22: =COUNTIFS('③スタートアップDB'!C5:C5,A22)-B22 | D22: =B22+C22
A23: 素材・化学 | B23: =COUNTIFS('③スタートアップDB'!C5:C5,A23,'③スタートアップDB'!G5:G5,"日本") | C23: =COUNTIFS('③スタートアップDB'!C5:C5,A23)-B23 | D23: =B23+C23
A24: 半導体・エレクトロニクス | B24: =COUNTIFS('③スタートアップDB'!C5:C5,A24,'③スタートアップDB'!G5:G5,"日本") | C24: =COUNTIFS('③スタートアップDB'!C5:C5,A24)-B24 | D24: =B24+C24
A25: ロボティクス・ドローン | B25: =COUNTIFS('③スタートアップDB'!C5:C5,A25,'③スタートアップDB'!G5:G5,"日本") | C25: =COUNTIFS('③スタートアップDB'!C5:C5,A25)-B25 | D25: =B25+C25
A26: 製造DX・産業機器 | B26: =COUNTIFS('③スタートアップDB'!C5:C5,A26,'③スタートアップDB'!G5:G5,"日本") | C26: =COUNTIFS('③スタートアップDB'!C5:C5,A26)-B26 | D26: =B26+C26
A27: 物流・サプライチェーン | B27: =COUNTIFS('③スタートアップDB'!C5:C5,A27,'③スタートアップDB'!G5:G5,"日本") | C27: =COUNTIFS('③スタートアップDB'!C5:C5,A27)-B27 | D27: =B27+C27
A28: 農業・食品 | B28: =COUNTIFS('③スタートアップDB'!C5:C5,A28,'③スタートアップDB'!G5:G5,"日本") | C28: =COUNTIFS('③スタートアップDB'!C5:C5,A28)-B28 | D28: =B28+C28
A29: 建設・不動産・インフラ | B29: =COUNTIFS('③スタートアップDB'!C5:C5,A29,'③スタートアップDB'!G5:G5,"日本") | C29: =COUNTIFS('③スタートアップDB'!C5:C5,A29)-B29 | D29: =B29+C29
A30: 小売・EC・消費者サービス | B30: =COUNTIFS('③スタートアップDB'!C5:C5,A30,'③スタートアップDB'!G5:G5,"日本") | C30: =COUNTIFS('③スタートアップDB'!C5:C5,A30)-B30 | D30: =B30+C30
A31: HR・教育 | B31: =COUNTIFS('③スタートアップDB'!C5:C5,A31,'③スタートアップDB'!G5:G5,"日本") | C31: =COUNTIFS('③スタートアップDB'!C5:C5,A31)-B31 | D31: =B31+C31
A32: セキュリティ・通信 | B32: =COUNTIFS('③スタートアップDB'!C5:C5,A32,'③スタートアップDB'!G5:G5,"日本") | C32: =COUNTIFS('③スタートアップDB'!C5:C5,A32)-B32 | D32: =B32+C32
A33: エンタメ・メディア・ゲーム | B33: =COUNTIFS('③スタートアップDB'!C5:C5,A33,'③スタートアップDB'!G5:G5,"日本") | C33: =COUNTIFS('③スタートアップDB'!C5:C5,A33)-B33 | D33: =B33+C33
A34: その他 | B34: =COUNTIFS('③スタートアップDB'!C5:C5,A34,'③スタートアップDB'!G5:G5,"日本") | C34: =COUNTIFS('③スタートアップDB'!C5:C5,A34)-B34 | D34: =B34+C34
A35: 合計 | B35: =SUM(B15:B34) | C35: =SUM(C15:C34) | D35: =SUM(D15:D34)
A36: カバー分類数 | B36: =SUMPRODUCT((D15:D34>0)*1) | C36: / 20分類
A38: C. 製造技術分類(追加タグ)の集計
A39: 製造技術分類 | B39: 件数
A40: AI・データ(シミュレーション/CAE) | B40: =COUNTIF('③スタートアップDB'!D5:D5,A40)
A41: センシング | B41: =COUNTIF('③スタートアップDB'!D5:D5,A41)
A42: 検査・品質 | B42: =COUNTIF('③スタートアップDB'!D5:D5,A42)
A43: 予知保全 | B43: =COUNTIF('③スタートアップDB'!D5:D5,A43)
...

Sheet ②項目定義
A1: 項目定義
A2: 上段=スタートアップDB(40項目・事実のみ)/下段=マッチングDB(キー4列+本編30列+要約13列・評価)。詳細ルールはスキルSKILL.md。
A4: A. スタートアップDB(40項目)
A5: フィールド | B5: 内容・記入ルール | C5: マッチングでの使われ方
A6: startup_id | B6: 一意ID(国内=法人番号、無ければjp-社名/海外=ドメイン) | C6: マッチングDBとの結合キー
A7: 業界分類 | B7: 20分類から1つ(包括的タクソノミー) | C7: 突合①: 粗い絞り込み
A8: 製造技術分類 | B8: 8分類、製造業関連の場合のみ | C8: 突合①: 製造系アセットの絞り込み
A9: 企業名/企業名(日) | B9: 英名/日本語名(国内のみ) | C9: (識別)
A10: 国/都市 | B10: 国は日本語表記 | C10: 実現性評価: 地理
A11: 設立年/Webサイト/従業員 | B11: 事実のみ。従業員は「約N名(推定)」可 | C11: 定義判定・体制規模
A12: ステージ(原文/統一) | B12: 統一語彙: シード/シリーズA/B/C/D以降/グラント・デットのみ/不明 | C12: 協業タイプの当たり付け・集計
A13: 累計調達額/調達額USD(百万) | B13: 原文表記+USD換算数値(合算・換算は明記) | C13: ソート・優先度付け
A14: 直近ラウンド/直近調達日 | B14: 「YYYY年M月・金額・ラウンド名」+ISO日付 | C14: 鮮度・勢い
A15: 主要投資家 | B15: リード優先 | C15: 競合CVCの確認
A16: 事業概要/主要プロダクト/プロダクト概要 | B16: 日本語1-2文 | C16: ◎マッチング対象の実体
... A27: 出典URL/情報取得日/取得経路 | B27: 検証可能性と再現性の記録 | C27: 裏取り・鮮度管理
A29: B. マッチングDB(キー4列+本編30列+要約ブロック13列)
A30: 列(グループ) | B30: 内容・記入ルール
A31: キー4列(スタートアップID/企業名/アセットID/協業タイプ) | B31: 両DBへの結合キー。協業タイプ=技術提供・ライセンス/共同開発/調達・ツール導入/顧客候補/出資
A32: 転記4列(事業概要/主要プロダクト/プロダクト概要/コア技術) | B32: ③スタートアップDBからstartup_idで自動転記(Excel生成時)。マッチした相手の実体をこのシート内で確認できるようにするための参照列。手で書かない
A33: ⑤アセット情報シート | B33: マッチングに使用したアセットの全情報(名称/成熟度/概要/スペック/機能分解/拡張可能性/NG条件)を転記して保存。build_startup_db.py --assets で生成
A34: No/タイトル/タグ/概要 | B34: 協業アイデアの識別・要約(概要=アセットの何を相手の何と組み合わせ何を生むか)
A35: 市場規模(一覧)/CAGR(一覧)/市場規模詳細/CAGR詳細 | B35: スタートアップDBから転記(協業固有の市場ならその値・出典必須)
A36: 総合スコア(一覧)/総合評価スコア | B36: 同値(一覧表示用と詳細用)。スコア10種の加重平均・0-10・小数1桁
A37: 自己評価ランク | B37: 総合評価スコアから自動導出: A=8.0以上/B=6.0〜7.9/C=6.0未満
A38: 想定顧客/課題/解決方法/収益モデル/アイデアの強み | B38: 協業アイデアとしての記述(主語=アセット×スタートアップ)
A39: 使用するコア技術 | B39: 「アセット側: …/スタートアップ側: …」の形式で両方明記
A40: スコア9種(各0-10の数値) | B40: 差別化(補完性含む: 相手と重複=競合=低)/技術実現性/アセット適合性/業界優位性/業界課題フィット/新規性/ミッション整合性/市場規模/CAGR。※「8/10」等の文字列は日付化するため禁止
A41: 未使用理由・採用障壁/コア機能の改善点 | B41: アセットの制約条件・協業の障壁/協業で埋めるべきギャップ
... A44: 要約ブロック13列(要約_コンセプト〜要約_成長性スコア) | B44: 一覧・他システム連携用の凝縮表記。コンセプト/想定市場/顧客/課題/解決方法/市場規模/CAGR/独自性/ミッション整合(各1文以内)+スコア4種(独自性/ミッション整合/市場規模/成長性、0-10数値)。本編列の内容を要約したもので矛盾させないこと

Sheet ③スタートアップDB
A1: スタートアップDB(0社)
A2: アセット非依存のマスタDB(事実のみ)。評価・マッチングは④マッチングDBで管理。
A4: No | B4: スタートアップID | C4: 業界分類 | D4: 製造技術分類 | E4: 企業名 | F4: 企業名(日) | G4: 国 | H4: 都市 | I4: 設立年 | J4: Webサイト | K4: 従業員(概算) | L4: ステージ(原文) | M4: ステージ(統一) | N4: 累計調達額 | O4: 調達額USD(百万) | P4: 直近ラウンド | Q4: 直近調達日 | R4: 主要投資家 | S4: 事業概要 | T4: 主要プロダクト | U4: プロダクト概要 | V4: 提供形態 | W4: 収益モデル | X4: 想定顧客 | Y4: 対象業界 | Z4: 主要顧客・パートナー | AA4: 課題 | AB4: 市場規模 | AC4: 市場規模詳細 | AD4: CAGR | AE4: CAGR詳細 | AF4: 技術キーワード | AG4: コア技術 | AH4: 差別化要素 | AI4: 成熟度 | AJ4: 定義適合 | AK4: 適合注記 | AL4: 主要リスク(事実) | AM4: 出典URL | AN4: 情報取得日 | AO4: 取得経路

Sheet ④マッチングDB
A1: マッチングDB(0件)
A2: アセット×スタートアップの協業アイデア評価(アイデア評価DB互換フォーマット)。スコアは0-10の数値。ランクは総合評価スコアから自動導出(A>=8.0/B>=6.0/C<6.0)。
A4: スタートアップID | B4: 企業名 | C4: 事業概要 | D4: 主要プロダクト | E4: プロダクト概要 | F4: コア技術 | G4: アセットID(名) | H4: 協業タイプ | I4: No | J4: タイトル | K4: タグ | L4: 概要 | M4: 市場規模(一覧) | N4: CAGR(一覧) | O4: 総合スコア(一覧) | P4: 自己評価ランク | Q4: 想定顧客 | R4: 課題 | S4: 解決方法 | T4: 収益モデル | U4: アイデアの強み | V4: 使用するコア技術 | W4: 差別化スコア | X4: 技術実現性スコア | Y4: アセット適合性スコア | Z4: 業界優位性スコア | AA4: 業界課題フィットスコア | AB4: 未使用理由・採用障壁 | AC4: コア機能の改善点 | AD4: 新規性スコア | AE4: ミッション整合性スコア | AF4: 市場規模詳細 | AG4: 市場規模スコア | AH4: CAGR詳細 | AI4: CAGRスコア | AJ4: 総合評価スコア | AK4: エージェントの思考根拠 | AL4: 主要リスク | AM4: 要約_コンセプト | AN4: 要約_想定市場 | AO4: 要約_顧客 | AP4: 要約_課題 | AQ4: 要約_解決方法 | AR4: 要約_市場規模 | AS4: 要約_CAGR | AT4: 要約_独自性 | AU4: 要約_ミッション整合 | AV4: 要約_独自性スコア | AW4: 要約_ミッション整合スコア | AX4: 要約_市場規模スコア | AY4: 要約_成長性スコア
